Tue, 01 Mar 2016 15:57:19 C:\Python27\lib\site-packages\werkzeug-0.10.4-py2.7.egg\werkzeug\_internal.py[line:87] INFO  * Detected change in 'E:\\mana_api\\mana_api\\api\\vm\\api_util.py', reloading
Tue, 01 Mar 2016 15:57:19 C:\Python27\lib\site-packages\werkzeug-0.10.4-py2.7.egg\werkzeug\_internal.py[line:87] INFO  * Restarting with stat
Tue, 01 Mar 2016 15:57:53 C:\Python27\lib\site-packages\werkzeug-0.10.4-py2.7.egg\werkzeug\_internal.py[line:87] INFO  * Detected change in 'E:\\mana_api\\mana_api\\api\\vm\\api_util.py', reloading
Tue, 01 Mar 2016 15:57:53 C:\Python27\lib\site-packages\werkzeug-0.10.4-py2.7.egg\werkzeug\_internal.py[line:87] INFO  * Restarting with stat
Tue, 01 Mar 2016 16:41:47 C:\Python27\lib\site-packages\werkzeug-0.10.4-py2.7.egg\werkzeug\_internal.py[line:87] INFO  * Running on http://0.0.0.0:8181/ (Press CTRL+C to quit)
Tue, 01 Mar 2016 16:41:47 C:\Python27\lib\site-packages\werkzeug-0.10.4-py2.7.egg\werkzeug\_internal.py[line:87] INFO  * Restarting with stat
Tue, 01 Mar 2016 16:42:56 C:\Python27\lib\site-packages\werkzeug-0.10.4-py2.7.egg\werkzeug\_internal.py[line:87] INFO  * Detected change in 'E:\\mana_api\\mana_api\\api\\pm_mana.py', reloading
Tue, 01 Mar 2016 16:42:56 C:\Python27\lib\site-packages\werkzeug-0.10.4-py2.7.egg\werkzeug\_internal.py[line:87] INFO  * Restarting with stat
Tue, 01 Mar 2016 17:09:27 C:\Python27\lib\site-packages\werkzeug-0.10.4-py2.7.egg\werkzeug\_internal.py[line:87] INFO  * Detected change in 'E:\\mana_api\\mana_api\\api\\vm\\api_util.py', reloading
Tue, 01 Mar 2016 17:09:27 C:\Python27\lib\site-packages\werkzeug-0.10.4-py2.7.egg\werkzeug\_internal.py[line:87] INFO  * Restarting with stat
Tue, 01 Mar 2016 17:12:16 C:\Python27\lib\site-packages\werkzeug-0.10.4-py2.7.egg\werkzeug\_internal.py[line:87] INFO  * Detected change in 'E:\\mana_api\\mana_api\\api\\vm\\api_util.py', reloading
Tue, 01 Mar 2016 17:12:16 C:\Python27\lib\site-packages\werkzeug-0.10.4-py2.7.egg\werkzeug\_internal.py[line:87] INFO  * Restarting with stat
Tue, 01 Mar 2016 17:18:08 C:\Python27\lib\site-packages\werkzeug-0.10.4-py2.7.egg\werkzeug\_internal.py[line:87] INFO  * Detected change in 'E:\\mana_api\\mana_api\\api\\vm\\api_util.py', reloading
Tue, 01 Mar 2016 17:18:08 C:\Python27\lib\site-packages\werkzeug-0.10.4-py2.7.egg\werkzeug\_internal.py[line:87] INFO  * Restarting with stat
Tue, 01 Mar 2016 17:42:34 C:\Python27\lib\site-packages\werkzeug-0.10.4-py2.7.egg\werkzeug\_internal.py[line:87] INFO  * Detected change in 'E:\\mana_api\\mana_api\\api\\vm\\api_util.py', reloading
Tue, 01 Mar 2016 17:42:34 C:\Python27\lib\site-packages\werkzeug-0.10.4-py2.7.egg\werkzeug\_internal.py[line:87] INFO  * Restarting with stat
Tue, 01 Mar 2016 17:46:35 C:\Python27\lib\site-packages\werkzeug-0.10.4-py2.7.egg\werkzeug\_internal.py[line:87] INFO  * Detected change in 'E:\\mana_api\\mana_api\\api\\vm\\api_util.py', reloading
Tue, 01 Mar 2016 17:46:35 C:\Python27\lib\site-packages\werkzeug-0.10.4-py2.7.egg\werkzeug\_internal.py[line:87] INFO  * Restarting with stat
Tue, 01 Mar 2016 17:49:13 C:\Python27\lib\site-packages\werkzeug-0.10.4-py2.7.egg\werkzeug\_internal.py[line:87] INFO  * Detected change in 'E:\\mana_api\\mana_api\\api\\vm\\api_util.py', reloading
Tue, 01 Mar 2016 17:49:13 C:\Python27\lib\site-packages\werkzeug-0.10.4-py2.7.egg\werkzeug\_internal.py[line:87] INFO  * Restarting with stat
Tue, 01 Mar 2016 18:14:32 C:\Python27\lib\site-packages\werkzeug-0.10.4-py2.7.egg\werkzeug\_internal.py[line:87] INFO  * Detected change in 'E:\\mana_api\\mana_api\\api\\vm\\api_util.py', reloading
Tue, 01 Mar 2016 18:14:32 C:\Python27\lib\site-packages\werkzeug-0.10.4-py2.7.egg\werkzeug\_internal.py[line:87] INFO  * Restarting with stat
Wed, 02 Mar 2016 10:44:41 C:\Python27\lib\site-packages\werkzeug-0.10.4-py2.7.egg\werkzeug\_internal.py[line:87] INFO  * Detected change in 'E:\\mana_api\\mana_api\\api\\vm\\api_util.py', reloading
Wed, 02 Mar 2016 10:44:41 C:\Python27\lib\site-packages\werkzeug-0.10.4-py2.7.egg\werkzeug\_internal.py[line:87] INFO  * Restarting with stat
Wed, 02 Mar 2016 14:29:31 C:\Python27\lib\site-packages\werkzeug-0.10.4-py2.7.egg\werkzeug\_internal.py[line:87] INFO  * Detected change in 'E:\\mana_api\\mana_api\\api\\vm\\api_util.py', reloading
Wed, 02 Mar 2016 14:29:31 C:\Python27\lib\site-packages\werkzeug-0.10.4-py2.7.egg\werkzeug\_internal.py[line:87] INFO  * Restarting with stat
Wed, 02 Mar 2016 14:44:11 C:\Python27\lib\site-packages\werkzeug-0.10.4-py2.7.egg\werkzeug\_internal.py[line:87] INFO  * Detected change in 'E:\\mana_api\\mana_api\\api\\vm\\api_util.py', reloading
Wed, 02 Mar 2016 14:44:11 C:\Python27\lib\site-packages\werkzeug-0.10.4-py2.7.egg\werkzeug\_internal.py[line:87] INFO  * Restarting with stat
Wed, 02 Mar 2016 14:45:13 C:\Python27\lib\site-packages\werkzeug-0.10.4-py2.7.egg\werkzeug\_internal.py[line:87] INFO  * Detected change in 'E:\\mana_api\\mana_api\\api\\vm\\api_util.py', reloading
Wed, 02 Mar 2016 14:45:13 C:\Python27\lib\site-packages\werkzeug-0.10.4-py2.7.egg\werkzeug\_internal.py[line:87] INFO  * Restarting with stat
Wed, 02 Mar 2016 16:29:20 C:\Python27\lib\site-packages\werkzeug-0.10.4-py2.7.egg\werkzeug\_internal.py[line:87] INFO  * Detected change in 'E:\\mana_api\\mana_api\\api\\vm\\api_util.py', reloading
Wed, 02 Mar 2016 16:29:20 C:\Python27\lib\site-packages\werkzeug-0.10.4-py2.7.egg\werkzeug\_internal.py[line:87] INFO  * Restarting with stat
Wed, 02 Mar 2016 16:44:35 C:\Python27\lib\site-packages\werkzeug-0.10.4-py2.7.egg\werkzeug\_internal.py[line:87] INFO  * Detected change in 'E:\\mana_api\\mana_api\\api\\vm\\api_util.py', reloading
Wed, 02 Mar 2016 16:44:35 C:\Python27\lib\site-packages\werkzeug-0.10.4-py2.7.egg\werkzeug\_internal.py[line:87] INFO  * Restarting with stat
Wed, 02 Mar 2016 16:45:10 C:\Python27\lib\site-packages\werkzeug-0.10.4-py2.7.egg\werkzeug\_internal.py[line:87] INFO  * Detected change in 'E:\\mana_api\\mana_api\\api\\vm\\api_util.py', reloading
Wed, 02 Mar 2016 16:45:10 C:\Python27\lib\site-packages\werkzeug-0.10.4-py2.7.egg\werkzeug\_internal.py[line:87] INFO  * Restarting with stat
Wed, 02 Mar 2016 16:45:28 C:\Python27\lib\site-packages\werkzeug-0.10.4-py2.7.egg\werkzeug\_internal.py[line:87] INFO  * Detected change in 'E:\\mana_api\\mana_api\\api\\vm\\api_util.py', reloading
Wed, 02 Mar 2016 16:45:28 C:\Python27\lib\site-packages\werkzeug-0.10.4-py2.7.egg\werkzeug\_internal.py[line:87] INFO  * Restarting with stat
Fri, 04 Mar 2016 10:36:35 C:\Python27\lib\site-packages\werkzeug-0.10.4-py2.7.egg\werkzeug\_internal.py[line:87] INFO  * Detected change in 'E:\\mana_api\\mana_api\\apiUtil.py', reloading
Fri, 04 Mar 2016 10:36:36 C:\Python27\lib\site-packages\werkzeug-0.10.4-py2.7.egg\werkzeug\_internal.py[line:87] INFO  * Restarting with stat
Fri, 04 Mar 2016 10:39:51 C:\Python27\lib\site-packages\werkzeug-0.10.4-py2.7.egg\werkzeug\_internal.py[line:87] INFO  * Detected change in 'E:\\mana_api\\mana_api\\api\\vm\\api_util.py', reloading
Fri, 04 Mar 2016 10:39:51 C:\Python27\lib\site-packages\werkzeug-0.10.4-py2.7.egg\werkzeug\_internal.py[line:87] INFO  * Restarting with stat
Fri, 04 Mar 2016 10:42:01 C:\Python27\lib\site-packages\werkzeug-0.10.4-py2.7.egg\werkzeug\_internal.py[line:87] INFO  * Detected change in 'E:\\mana_api\\mana_api\\api\\vm\\api_util.py', reloading
Fri, 04 Mar 2016 10:42:01 C:\Python27\lib\site-packages\werkzeug-0.10.4-py2.7.egg\werkzeug\_internal.py[line:87] INFO  * Restarting with stat
Fri, 04 Mar 2016 16:53:00 C:\Python27\lib\site-packages\werkzeug-0.10.4-py2.7.egg\werkzeug\_internal.py[line:87] INFO  * Detected change in 'E:\\mana_api\\mana_api\\api\\pm_mana.py', reloading
Fri, 04 Mar 2016 16:53:00 C:\Python27\lib\site-packages\werkzeug-0.10.4-py2.7.egg\werkzeug\_internal.py[line:87] INFO  * Restarting with stat
Fri, 04 Mar 2016 16:55:01 E:\mana_api\mana_api\api\vm\nova.py[line:47] INFO Request: get vm servers list tenant_id => 74d4bda6aa1c466d8cb1f2b8eac79567 region => shanghai from => None to => None
Fri, 04 Mar 2016 16:55:01 E:\mana_api\mana_api\api\vm\api_util.py[line:67] INFO scloudm response: {u'servers': [{u'OS-EXT-STS:task_state': None, u'addresses': {}, u'links': [{u'href': u'http://192.168.39.171:8774/v2/74d4bda6aa1c466d8cb1f2b8eac79567/servers/c580a68a-b8c9-45ff-916b-65c153f9d9d2', u'rel': u'self'}, {u'href': u'http://192.168.39.171:8774/74d4bda6aa1c466d8cb1f2b8eac79567/servers/c580a68a-b8c9-45ff-916b-65c153f9d9d2', u'rel': u'bookmark'}], u'image': u'', u'OS-EXT-STS:vm_state': u'error', u'OS-EXT-SRV-ATTR:instance_name': u'instance-000000b6', u'OS-SRV-USG:launched_at': None, u'flavor': {u'id': u'09a753f6-21c5-43b5-ba06-7c0b251aefb3', u'links': [{u'href': u'http://192.168.39.171:8774/74d4bda6aa1c466d8cb1f2b8eac79567/flavors/09a753f6-21c5-43b5-ba06-7c0b251aefb3', u'rel': u'bookmark'}]}, u'id': u'c580a68a-b8c9-45ff-916b-65c153f9d9d2', u'user_id': u'cc13d74dfbc14ca6909f050b5b589c83', u'OS-DCF:diskConfig': u'AUTO', u'accessIPv4': u'', u'accessIPv6': u'', u'OS-EXT-STS:power_state': 0, u'OS-EXT-AZ:availability_zone': u'nova', u'config_drive': u'', u'status': u'ERROR', u'updated': u'2016-02-19T07:52:41Z', u'hostId': u'5464aced14e9844a3c858b50b43f8be6231ad8349f6d06005523d739', u'OS-EXT-SRV-ATTR:host': u'SH-F1-Cloud23', u'OS-SRV-USG:terminated_at': None, u'key_name': None, u'OS-EXT-SRV-ATTR:hypervisor_hostname': u'SH-F1-Cloud23', u'name': u'1111-c580a68a-b8c9-45ff-916b-65c153f9d9d2', u'created': u'2016-02-19T07:49:06Z', u'tenant_id': u'74d4bda6aa1c466d8cb1f2b8eac79567', u'os-extended-volumes:volumes_attached': [], u'fault': {u'message': u'Block Device Mapping is Invalid.', u'code': 400, u'created': u'2016-02-19T07:52:41Z'}, u'metadata': {}}, {u'OS-EXT-STS:task_state': None, u'addresses': {}, u'links': [{u'href': u'http://192.168.39.171:8774/v2/74d4bda6aa1c466d8cb1f2b8eac79567/servers/1cdcfd87-1eb7-48ff-89c5-449b2903f1d0', u'rel': u'self'}, {u'href': u'http://192.168.39.171:8774/74d4bda6aa1c466d8cb1f2b8eac79567/servers/1cdcfd87-1eb7-48ff-89c5-449b2903f1d0', u'rel': u'bookmark'}], u'image': u'', u'OS-EXT-STS:vm_state': u'error', u'OS-EXT-SRV-ATTR:instance_name': u'instance-000000b5', u'OS-SRV-USG:launched_at': None, u'flavor': {u'id': u'09a753f6-21c5-43b5-ba06-7c0b251aefb3', u'links': [{u'href': u'http://192.168.39.171:8774/74d4bda6aa1c466d8cb1f2b8eac79567/flavors/09a753f6-21c5-43b5-ba06-7c0b251aefb3', u'rel': u'bookmark'}]}, u'id': u'1cdcfd87-1eb7-48ff-89c5-449b2903f1d0', u'user_id': u'cc13d74dfbc14ca6909f050b5b589c83', u'OS-DCF:diskConfig': u'AUTO', u'accessIPv4': u'', u'accessIPv6': u'', u'OS-EXT-STS:power_state': 0, u'OS-EXT-AZ:availability_zone': u'nova', u'config_drive': u'', u'status': u'ERROR', u'updated': u'2016-02-19T07:52:41Z', u'hostId': u'5464aced14e9844a3c858b50b43f8be6231ad8349f6d06005523d739', u'OS-EXT-SRV-ATTR:host': u'SH-F1-Cloud23', u'OS-SRV-USG:terminated_at': None, u'key_name': None, u'OS-EXT-SRV-ATTR:hypervisor_hostname': u'SH-F1-Cloud23', u'name': u'1111-1cdcfd87-1eb7-48ff-89c5-449b2903f1d0', u'created': u'2016-02-19T07:49:06Z', u'tenant_id': u'74d4bda6aa1c466d8cb1f2b8eac79567', u'os-extended-volumes:volumes_attached': [], u'fault': {u'message': u'Block Device Mapping is Invalid.', u'code': 400, u'created': u'2016-02-19T07:52:41Z'}, u'metadata': {}}, {u'OS-EXT-STS:task_state': None, u'addresses': {}, u'links': [{u'href': u'http://192.168.39.171:8774/v2/74d4bda6aa1c466d8cb1f2b8eac79567/servers/ee9f781a-05b4-4fa9-ad17-a0295f1f2f91', u'rel': u'self'}, {u'href': u'http://192.168.39.171:8774/74d4bda6aa1c466d8cb1f2b8eac79567/servers/ee9f781a-05b4-4fa9-ad17-a0295f1f2f91', u'rel': u'bookmark'}], u'image': u'', u'OS-EXT-STS:vm_state': u'error', u'OS-EXT-SRV-ATTR:instance_name': u'instance-000000b4', u'OS-SRV-USG:launched_at': None, u'flavor': {u'id': u'09a753f6-21c5-43b5-ba06-7c0b251aefb3', u'links': [{u'href': u'http://192.168.39.171:8774/74d4bda6aa1c466d8cb1f2b8eac79567/flavors/09a753f6-21c5-43b5-ba06-7c0b251aefb3', u'rel': u'bookmark'}]}, u'id': u'ee9f781a-05b4-4fa9-ad17-a0295f1f2f91', u'user_id': u'cc13d74dfbc14ca6909f050b5b589c83', u'OS-DCF:diskConfig': u'AUTO', u'accessIPv4': u'', u'accessIPv6': u'', u'OS-EXT-STS:power_state': 0, u'OS-EXT-AZ:availability_zone': u'nova', u'config_drive': u'', u'status': u'ERROR', u'updated': u'2016-02-19T07:49:10Z', u'hostId': u'5464aced14e9844a3c858b50b43f8be6231ad8349f6d06005523d739', u'OS-EXT-SRV-ATTR:host': u'SH-F1-Cloud23', u'OS-SRV-USG:terminated_at': None, u'key_name': None, u'OS-EXT-SRV-ATTR:hypervisor_hostname': u'SH-F1-Cloud23', u'name': u'1111-ee9f781a-05b4-4fa9-ad17-a0295f1f2f91', u'created': u'2016-02-19T07:49:05Z', u'tenant_id': u'74d4bda6aa1c466d8cb1f2b8eac79567', u'os-extended-volumes:volumes_attached': [], u'fault': {u'message': u'Block Device Mapping is Invalid.', u'code': 400, u'created': u'2016-02-19T07:49:10Z'}, u'metadata': {}}]}
Fri, 04 Mar 2016 16:55:01 C:\Python27\lib\site-packages\werkzeug-0.10.4-py2.7.egg\werkzeug\_internal.py[line:87] INFO 192.168.39.170 - - [04/Mar/2016 16:55:01] "GET /mana_api/vm?tenant_id=74d4bda6aa1c466d8cb1f2b8eac79567&region=shanghai HTTP/1.1" 200 -
Fri, 04 Mar 2016 16:55:13 E:\mana_api\mana_api\api\vm\nova.py[line:47] INFO Request: get vm servers list tenant_id => 74d4bda6aa1c466d8cb1f2b8eac79567 region => shanghais from => None to => None
Fri, 04 Mar 2016 16:55:13 E:\mana_api\mana_api\api\vm\nova.py[line:53] ERROR Error with get vm_servers
Traceback (most recent call last):
  File "E:\mana_api\mana_api\api\vm\nova.py", line 50, in vm
    result = nova_list(new_token, user.get_endpoint(region, "nova"), f, t)
  File "E:\mana_api\mana_api\api\vm\api_util.py", line 64, in nova_list
    url = endpoint + '/servers/detail'
TypeError: unsupported operand type(s) for +: 'NoneType' and 'str'
Fri, 04 Mar 2016 16:55:13 C:\Python27\lib\site-packages\werkzeug-0.10.4-py2.7.egg\werkzeug\_internal.py[line:87] INFO 192.168.39.170 - - [04/Mar/2016 16:55:13] "GET /mana_api/vm?tenant_id=74d4bda6aa1c466d8cb1f2b8eac79567&region=shanghais HTTP/1.1" 400 -
Fri, 04 Mar 2016 16:56:21 E:\mana_api\mana_api\api\vm\nova.py[line:47] INFO Request: get vm servers list tenant_id => 74d4bda6aa1c466d8cb1f2b8eac79567 region => shanghais from => None to => None
Fri, 04 Mar 2016 16:56:21 E:\mana_api\mana_api\api\vm\nova.py[line:53] ERROR Error with get vm_servers
Traceback (most recent call last):
  File "E:\mana_api\mana_api\api\vm\nova.py", line 50, in vm
    result = nova_list(new_token, user.get_endpoint(region, "nova"), f, t)
  File "E:\mana_api\mana_api\api\vm\api_util.py", line 64, in nova_list
    url = endpoint + '/servers/detail'
TypeError: unsupported operand type(s) for +: 'NoneType' and 'str'
Fri, 04 Mar 2016 16:56:21 C:\Python27\lib\site-packages\werkzeug-0.10.4-py2.7.egg\werkzeug\_internal.py[line:87] INFO 192.168.39.170 - - [04/Mar/2016 16:56:21] "GET /mana_api/vm?tenant_id=74d4bda6aa1c466d8cb1f2b8eac79567&region=shanghais HTTP/1.1" 400 -
Fri, 04 Mar 2016 16:57:33 C:\Python27\lib\site-packages\werkzeug-0.10.4-py2.7.egg\werkzeug\_internal.py[line:87] INFO 192.168.39.170 - - [04/Mar/2016 16:57:33] "GET /mana_api/vm?tenant_id=74d4bda6aa1c466d8cb1f2b8eac795672&region=shanghai HTTP/1.1" 403 -
Fri, 04 Mar 2016 16:57:41 C:\Python27\lib\site-packages\werkzeug-0.10.4-py2.7.egg\werkzeug\_internal.py[line:87] INFO 192.168.39.170 - - [04/Mar/2016 16:57:41] "GET /mana_api/vm?tenant_id=74d4bda6aa1c466d8cb1f2b8eac795673445&region=shanghai HTTP/1.1" 403 -
Fri, 04 Mar 2016 16:57:45 E:\mana_api\mana_api\api\vm\nova.py[line:47] INFO Request: get vm servers list tenant_id => 74d4bda6aa1c466d8cb1f2b8eac79567 region => shanghai from => None to => None
Fri, 04 Mar 2016 16:57:45 E:\mana_api\mana_api\api\vm\api_util.py[line:67] INFO scloudm response: {u'servers': [{u'OS-EXT-STS:task_state': None, u'addresses': {}, u'links': [{u'href': u'http://192.168.39.171:8774/v2/74d4bda6aa1c466d8cb1f2b8eac79567/servers/c580a68a-b8c9-45ff-916b-65c153f9d9d2', u'rel': u'self'}, {u'href': u'http://192.168.39.171:8774/74d4bda6aa1c466d8cb1f2b8eac79567/servers/c580a68a-b8c9-45ff-916b-65c153f9d9d2', u'rel': u'bookmark'}], u'image': u'', u'OS-EXT-STS:vm_state': u'error', u'OS-EXT-SRV-ATTR:instance_name': u'instance-000000b6', u'OS-SRV-USG:launched_at': None, u'flavor': {u'id': u'09a753f6-21c5-43b5-ba06-7c0b251aefb3', u'links': [{u'href': u'http://192.168.39.171:8774/74d4bda6aa1c466d8cb1f2b8eac79567/flavors/09a753f6-21c5-43b5-ba06-7c0b251aefb3', u'rel': u'bookmark'}]}, u'id': u'c580a68a-b8c9-45ff-916b-65c153f9d9d2', u'user_id': u'cc13d74dfbc14ca6909f050b5b589c83', u'OS-DCF:diskConfig': u'AUTO', u'accessIPv4': u'', u'accessIPv6': u'', u'OS-EXT-STS:power_state': 0, u'OS-EXT-AZ:availability_zone': u'nova', u'config_drive': u'', u'status': u'ERROR', u'updated': u'2016-02-19T07:52:41Z', u'hostId': u'5464aced14e9844a3c858b50b43f8be6231ad8349f6d06005523d739', u'OS-EXT-SRV-ATTR:host': u'SH-F1-Cloud23', u'OS-SRV-USG:terminated_at': None, u'key_name': None, u'OS-EXT-SRV-ATTR:hypervisor_hostname': u'SH-F1-Cloud23', u'name': u'1111-c580a68a-b8c9-45ff-916b-65c153f9d9d2', u'created': u'2016-02-19T07:49:06Z', u'tenant_id': u'74d4bda6aa1c466d8cb1f2b8eac79567', u'os-extended-volumes:volumes_attached': [], u'fault': {u'message': u'Block Device Mapping is Invalid.', u'code': 400, u'created': u'2016-02-19T07:52:41Z'}, u'metadata': {}}, {u'OS-EXT-STS:task_state': None, u'addresses': {}, u'links': [{u'href': u'http://192.168.39.171:8774/v2/74d4bda6aa1c466d8cb1f2b8eac79567/servers/1cdcfd87-1eb7-48ff-89c5-449b2903f1d0', u'rel': u'self'}, {u'href': u'http://192.168.39.171:8774/74d4bda6aa1c466d8cb1f2b8eac79567/servers/1cdcfd87-1eb7-48ff-89c5-449b2903f1d0', u'rel': u'bookmark'}], u'image': u'', u'OS-EXT-STS:vm_state': u'error', u'OS-EXT-SRV-ATTR:instance_name': u'instance-000000b5', u'OS-SRV-USG:launched_at': None, u'flavor': {u'id': u'09a753f6-21c5-43b5-ba06-7c0b251aefb3', u'links': [{u'href': u'http://192.168.39.171:8774/74d4bda6aa1c466d8cb1f2b8eac79567/flavors/09a753f6-21c5-43b5-ba06-7c0b251aefb3', u'rel': u'bookmark'}]}, u'id': u'1cdcfd87-1eb7-48ff-89c5-449b2903f1d0', u'user_id': u'cc13d74dfbc14ca6909f050b5b589c83', u'OS-DCF:diskConfig': u'AUTO', u'accessIPv4': u'', u'accessIPv6': u'', u'OS-EXT-STS:power_state': 0, u'OS-EXT-AZ:availability_zone': u'nova', u'config_drive': u'', u'status': u'ERROR', u'updated': u'2016-02-19T07:52:41Z', u'hostId': u'5464aced14e9844a3c858b50b43f8be6231ad8349f6d06005523d739', u'OS-EXT-SRV-ATTR:host': u'SH-F1-Cloud23', u'OS-SRV-USG:terminated_at': None, u'key_name': None, u'OS-EXT-SRV-ATTR:hypervisor_hostname': u'SH-F1-Cloud23', u'name': u'1111-1cdcfd87-1eb7-48ff-89c5-449b2903f1d0', u'created': u'2016-02-19T07:49:06Z', u'tenant_id': u'74d4bda6aa1c466d8cb1f2b8eac79567', u'os-extended-volumes:volumes_attached': [], u'fault': {u'message': u'Block Device Mapping is Invalid.', u'code': 400, u'created': u'2016-02-19T07:52:41Z'}, u'metadata': {}}, {u'OS-EXT-STS:task_state': None, u'addresses': {}, u'links': [{u'href': u'http://192.168.39.171:8774/v2/74d4bda6aa1c466d8cb1f2b8eac79567/servers/ee9f781a-05b4-4fa9-ad17-a0295f1f2f91', u'rel': u'self'}, {u'href': u'http://192.168.39.171:8774/74d4bda6aa1c466d8cb1f2b8eac79567/servers/ee9f781a-05b4-4fa9-ad17-a0295f1f2f91', u'rel': u'bookmark'}], u'image': u'', u'OS-EXT-STS:vm_state': u'error', u'OS-EXT-SRV-ATTR:instance_name': u'instance-000000b4', u'OS-SRV-USG:launched_at': None, u'flavor': {u'id': u'09a753f6-21c5-43b5-ba06-7c0b251aefb3', u'links': [{u'href': u'http://192.168.39.171:8774/74d4bda6aa1c466d8cb1f2b8eac79567/flavors/09a753f6-21c5-43b5-ba06-7c0b251aefb3', u'rel': u'bookmark'}]}, u'id': u'ee9f781a-05b4-4fa9-ad17-a0295f1f2f91', u'user_id': u'cc13d74dfbc14ca6909f050b5b589c83', u'OS-DCF:diskConfig': u'AUTO', u'accessIPv4': u'', u'accessIPv6': u'', u'OS-EXT-STS:power_state': 0, u'OS-EXT-AZ:availability_zone': u'nova', u'config_drive': u'', u'status': u'ERROR', u'updated': u'2016-02-19T07:49:10Z', u'hostId': u'5464aced14e9844a3c858b50b43f8be6231ad8349f6d06005523d739', u'OS-EXT-SRV-ATTR:host': u'SH-F1-Cloud23', u'OS-SRV-USG:terminated_at': None, u'key_name': None, u'OS-EXT-SRV-ATTR:hypervisor_hostname': u'SH-F1-Cloud23', u'name': u'1111-ee9f781a-05b4-4fa9-ad17-a0295f1f2f91', u'created': u'2016-02-19T07:49:05Z', u'tenant_id': u'74d4bda6aa1c466d8cb1f2b8eac79567', u'os-extended-volumes:volumes_attached': [], u'fault': {u'message': u'Block Device Mapping is Invalid.', u'code': 400, u'created': u'2016-02-19T07:49:10Z'}, u'metadata': {}}]}
Fri, 04 Mar 2016 16:57:45 C:\Python27\lib\site-packages\werkzeug-0.10.4-py2.7.egg\werkzeug\_internal.py[line:87] INFO 192.168.39.170 - - [04/Mar/2016 16:57:45] "GET /mana_api/vm?tenant_id=74d4bda6aa1c466d8cb1f2b8eac79567&region=shanghai HTTP/1.1" 200 -
Fri, 04 Mar 2016 16:58:41 C:\Python27\lib\site-packages\werkzeug-0.10.4-py2.7.egg\werkzeug\_internal.py[line:87] INFO  * Detected change in 'E:\\mana_api\\mana_api\\api\\vm\\api_util.py', reloading
Fri, 04 Mar 2016 16:58:41 C:\Python27\lib\site-packages\werkzeug-0.10.4-py2.7.egg\werkzeug\_internal.py[line:87] INFO  * Restarting with stat
Fri, 04 Mar 2016 16:59:55 C:\Python27\lib\site-packages\werkzeug-0.10.4-py2.7.egg\werkzeug\_internal.py[line:87] INFO  * Detected change in 'E:\\mana_api\\mana_api\\api\\vm\\api_util.py', reloading
Fri, 04 Mar 2016 16:59:55 C:\Python27\lib\site-packages\werkzeug-0.10.4-py2.7.egg\werkzeug\_internal.py[line:87] INFO  * Restarting with stat
Fri, 04 Mar 2016 17:00:08 E:\mana_api\mana_api\api\vm\nova.py[line:47] INFO Request: get vm servers list tenant_id => 74d4bda6aa1c466d8cb1f2b8eac79567 region => shanghais from => None to => None
Fri, 04 Mar 2016 17:00:08 E:\mana_api\mana_api\api\vm\nova.py[line:56] ERROR Error with get vm_servers
Traceback (most recent call last):
  File "E:\mana_api\mana_api\api\vm\nova.py", line 50, in vm
    result = nova_list(new_token, user.get_endpoint(region, "nova"), f, t)
  File "E:\mana_api\mana_api\api\vm\api_util.py", line 65, in nova_list
    raise 'Invalid region'
TypeError: exceptions must be old-style classes or derived from BaseException, not str
Fri, 04 Mar 2016 17:00:08 C:\Python27\lib\site-packages\werkzeug-0.10.4-py2.7.egg\werkzeug\_internal.py[line:87] INFO 192.168.39.170 - - [04/Mar/2016 17:00:08] "GET /mana_api/vm?tenant_id=74d4bda6aa1c466d8cb1f2b8eac79567&region=shanghais HTTP/1.1" 400 -
Fri, 04 Mar 2016 17:06:45 C:\Python27\lib\site-packages\werkzeug-0.10.4-py2.7.egg\werkzeug\_internal.py[line:87] INFO  * Detected change in 'E:\\mana_api\\mana_api\\api\\vm\\api_util.py', reloading
Fri, 04 Mar 2016 17:06:45 C:\Python27\lib\site-packages\werkzeug-0.10.4-py2.7.egg\werkzeug\_internal.py[line:87] INFO  * Restarting with stat
Fri, 04 Mar 2016 17:09:43 C:\Python27\lib\site-packages\werkzeug-0.10.4-py2.7.egg\werkzeug\_internal.py[line:87] INFO  * Running on http://0.0.0.0:8181/ (Press CTRL+C to quit)
Fri, 04 Mar 2016 17:09:43 C:\Python27\lib\site-packages\werkzeug-0.10.4-py2.7.egg\werkzeug\_internal.py[line:87] INFO  * Restarting with stat
Fri, 04 Mar 2016 17:09:48 E:\mana_api\mana_api\api\vm\nova.py[line:47] INFO Request: get vm servers list tenant_id => 74d4bda6aa1c466d8cb1f2b8eac79567 region => shanghais from => None to => None
Fri, 04 Mar 2016 17:09:48 E:\mana_api\mana_api\api\vm\nova.py[line:53] ERROR MyError raised
Traceback (most recent call last):
  File "E:\mana_api\mana_api\api\vm\nova.py", line 50, in vm
    result = nova_list(new_token, user.get_endpoint(region, "nova"), f, t)
  File "E:\mana_api\mana_api\api\vm\api_util.py", line 73, in nova_list
    raise MyError('无效的区域'.decode('utf-8'))
MyError: u'\u65e0\u6548\u7684\u533a\u57df'
Fri, 04 Mar 2016 17:09:48 C:\Python27\lib\site-packages\werkzeug-0.10.4-py2.7.egg\werkzeug\_internal.py[line:87] INFO 192.168.39.170 - - [04/Mar/2016 17:09:48] "GET /mana_api/vm?tenant_id=74d4bda6aa1c466d8cb1f2b8eac79567&region=shanghais HTTP/1.1" 400 -
Fri, 04 Mar 2016 17:10:02 C:\Python27\lib\site-packages\werkzeug-0.10.4-py2.7.egg\werkzeug\_internal.py[line:87] INFO  * Detected change in 'E:\\mana_api\\mana_api\\api\\vm\\nova.py', reloading
Fri, 04 Mar 2016 17:10:02 C:\Python27\lib\site-packages\werkzeug-0.10.4-py2.7.egg\werkzeug\_internal.py[line:87] INFO  * Restarting with stat
Fri, 04 Mar 2016 17:10:33 C:\Python27\lib\site-packages\werkzeug-0.10.4-py2.7.egg\werkzeug\_internal.py[line:87] INFO  * Detected change in 'E:\\mana_api\\mana_api\\api\\vm\\nova.py', reloading
Fri, 04 Mar 2016 17:10:33 C:\Python27\lib\site-packages\werkzeug-0.10.4-py2.7.egg\werkzeug\_internal.py[line:87] INFO  * Restarting with stat
Fri, 04 Mar 2016 17:10:39 E:\mana_api\mana_api\api\vm\nova.py[line:47] INFO Request: get vm servers list tenant_id => 74d4bda6aa1c466d8cb1f2b8eac79567 region => shanghais from => None to => None
Fri, 04 Mar 2016 17:10:39 E:\mana_api\mana_api\api\vm\nova.py[line:53] ERROR MyError raised
Traceback (most recent call last):
  File "E:\mana_api\mana_api\api\vm\nova.py", line 50, in vm
    result = nova_list(new_token, user.get_endpoint(region, "nova"), f, t)
  File "E:\mana_api\mana_api\api\vm\api_util.py", line 73, in nova_list
    raise MyError('无效的区域'.decode('utf-8'))
MyError: u'\u65e0\u6548\u7684\u533a\u57df'
Fri, 04 Mar 2016 17:10:39 C:\Python27\lib\site-packages\werkzeug-0.10.4-py2.7.egg\werkzeug\_internal.py[line:87] INFO 192.168.39.170 - - [04/Mar/2016 17:10:39] "GET /mana_api/vm?tenant_id=74d4bda6aa1c466d8cb1f2b8eac79567&region=shanghais HTTP/1.1" 400 -
Fri, 04 Mar 2016 17:10:51 C:\Python27\lib\site-packages\werkzeug-0.10.4-py2.7.egg\werkzeug\_internal.py[line:87] INFO  * Detected change in 'E:\\mana_api\\mana_api\\api\\vm\\nova.py', reloading
Fri, 04 Mar 2016 17:10:51 C:\Python27\lib\site-packages\werkzeug-0.10.4-py2.7.egg\werkzeug\_internal.py[line:87] INFO  * Restarting with stat
Fri, 04 Mar 2016 17:10:53 E:\mana_api\mana_api\api\vm\nova.py[line:47] INFO Request: get vm servers list tenant_id => 74d4bda6aa1c466d8cb1f2b8eac79567 region => shanghais from => None to => None
Fri, 04 Mar 2016 17:10:53 E:\mana_api\mana_api\api\vm\nova.py[line:53] ERROR MyError raised
Traceback (most recent call last):
  File "E:\mana_api\mana_api\api\vm\nova.py", line 50, in vm
    result = nova_list(new_token, user.get_endpoint(region, "nova"), f, t)
  File "E:\mana_api\mana_api\api\vm\api_util.py", line 73, in nova_list
    raise MyError('无效的区域'.decode('utf-8'))
MyError: u'\u65e0\u6548\u7684\u533a\u57df'
Fri, 04 Mar 2016 17:10:53 C:\Python27\lib\site-packages\werkzeug-0.10.4-py2.7.egg\werkzeug\_internal.py[line:87] INFO 192.168.39.170 - - [04/Mar/2016 17:10:53] "GET /mana_api/vm?tenant_id=74d4bda6aa1c466d8cb1f2b8eac79567&region=shanghais HTTP/1.1" 400 -
Fri, 04 Mar 2016 17:13:47 E:\mana_api\mana_api\api\pm_mana.py[line:44] INFO Request: get pm servers list tenant_id => 74d4bda6aa1c466d8cb1f2b8eac79567 region => None from => None to => None
Fri, 04 Mar 2016 17:13:47 C:\Python27\lib\site-packages\werkzeug-0.10.4-py2.7.egg\werkzeug\_internal.py[line:87] INFO 192.168.39.170 - - [04/Mar/2016 17:13:47] "GET /mana_api/pm?tenant_id=74d4bda6aa1c466d8cb1f2b8eac79567 HTTP/1.1" 200 -
Fri, 04 Mar 2016 17:13:56 E:\mana_api\mana_api\api\pm_mana.py[line:44] INFO Request: get pm servers list tenant_id => 74d4bda6aa1c466d8cb1f2b8eac79567 region => gz from => None to => None
Fri, 04 Mar 2016 17:13:56 C:\Python27\lib\site-packages\werkzeug-0.10.4-py2.7.egg\werkzeug\_internal.py[line:87] INFO 192.168.39.170 - - [04/Mar/2016 17:13:56] "GET /mana_api/pm?tenant_id=74d4bda6aa1c466d8cb1f2b8eac79567&region=gz HTTP/1.1" 200 -
Fri, 04 Mar 2016 17:14:05 E:\mana_api\mana_api\api\pm_mana.py[line:44] INFO Request: get pm servers list tenant_id => 74d4bda6aa1c466d8cb1f2b8eac79567 region => pp from => None to => None
Fri, 04 Mar 2016 17:14:05 C:\Python27\lib\site-packages\werkzeug-0.10.4-py2.7.egg\werkzeug\_internal.py[line:87] INFO 192.168.39.170 - - [04/Mar/2016 17:14:05] "GET /mana_api/pm?tenant_id=74d4bda6aa1c466d8cb1f2b8eac79567&region=pp HTTP/1.1" 200 -
Fri, 04 Mar 2016 17:16:23 E:\mana_api\mana_api\api\pm_mana.py[line:44] INFO Request: get pm servers list tenant_id => 74d4bda6aa1c466d8cb1f2b8eac79567 region => pp from => None to => None
Fri, 04 Mar 2016 17:16:23 C:\Python27\lib\site-packages\werkzeug-0.10.4-py2.7.egg\werkzeug\_internal.py[line:87] INFO 192.168.39.170 - - [04/Mar/2016 17:16:23] "GET /mana_api/pm?tenant_id=74d4bda6aa1c466d8cb1f2b8eac79567&region=pp HTTP/1.1" 200 -
Mon, 07 Mar 2016 15:39:37 C:\Python27\lib\site-packages\werkzeug-0.10.4-py2.7.egg\werkzeug\_internal.py[line:87] INFO  * Detected change in 'E:\\mana_api\\mana_api\\api\\pm_mana.py', reloading
Mon, 07 Mar 2016 15:39:37 C:\Python27\lib\site-packages\werkzeug-0.10.4-py2.7.egg\werkzeug\_internal.py[line:87] INFO  * Restarting with stat
Mon, 07 Mar 2016 16:10:35 C:\Python27\lib\site-packages\werkzeug-0.10.4-py2.7.egg\werkzeug\_internal.py[line:87] INFO  * Detected change in 'E:\\mana_api\\mana_api\\models.py', reloading
Mon, 07 Mar 2016 16:10:35 C:\Python27\lib\site-packages\werkzeug-0.10.4-py2.7.egg\werkzeug\_internal.py[line:87] INFO  * Restarting with stat
Mon, 07 Mar 2016 16:10:57 C:\Python27\lib\site-packages\werkzeug-0.10.4-py2.7.egg\werkzeug\_internal.py[line:87] INFO  * Detected change in 'E:\\mana_api\\mana_api\\models.py', reloading
Mon, 07 Mar 2016 16:10:57 C:\Python27\lib\site-packages\werkzeug-0.10.4-py2.7.egg\werkzeug\_internal.py[line:87] INFO  * Restarting with stat
Mon, 07 Mar 2016 16:11:13 C:\Python27\lib\site-packages\werkzeug-0.10.4-py2.7.egg\werkzeug\_internal.py[line:87] INFO  * Detected change in 'E:\\mana_api\\mana_api\\models.py', reloading
Mon, 07 Mar 2016 16:11:13 C:\Python27\lib\site-packages\werkzeug-0.10.4-py2.7.egg\werkzeug\_internal.py[line:87] INFO  * Restarting with stat
Mon, 07 Mar 2016 16:11:17 C:\Python27\lib\site-packages\werkzeug-0.10.4-py2.7.egg\werkzeug\_internal.py[line:87] INFO  * Detected change in 'E:\\mana_api\\mana_api\\models.py', reloading
Mon, 07 Mar 2016 16:11:17 C:\Python27\lib\site-packages\werkzeug-0.10.4-py2.7.egg\werkzeug\_internal.py[line:87] INFO  * Restarting with stat
Mon, 07 Mar 2016 16:11:24 C:\Python27\lib\site-packages\werkzeug-0.10.4-py2.7.egg\werkzeug\_internal.py[line:87] INFO  * Detected change in 'E:\\mana_api\\mana_api\\models.py', reloading
Mon, 07 Mar 2016 16:11:24 C:\Python27\lib\site-packages\werkzeug-0.10.4-py2.7.egg\werkzeug\_internal.py[line:87] INFO  * Restarting with stat
Mon, 07 Mar 2016 16:11:34 C:\Python27\lib\site-packages\werkzeug-0.10.4-py2.7.egg\werkzeug\_internal.py[line:87] INFO  * Detected change in 'E:\\mana_api\\mana_api\\models.py', reloading
Mon, 07 Mar 2016 16:11:34 C:\Python27\lib\site-packages\werkzeug-0.10.4-py2.7.egg\werkzeug\_internal.py[line:87] INFO  * Restarting with stat
Mon, 07 Mar 2016 16:12:05 C:\Python27\lib\site-packages\werkzeug-0.10.4-py2.7.egg\werkzeug\_internal.py[line:87] INFO  * Detected change in 'E:\\mana_api\\mana_api\\models.py', reloading
Mon, 07 Mar 2016 16:12:05 C:\Python27\lib\site-packages\werkzeug-0.10.4-py2.7.egg\werkzeug\_internal.py[line:87] INFO  * Restarting with stat
Mon, 07 Mar 2016 16:12:13 C:\Python27\lib\site-packages\werkzeug-0.10.4-py2.7.egg\werkzeug\_internal.py[line:87] INFO  * Detected change in 'E:\\mana_api\\mana_api\\models.py', reloading
Mon, 07 Mar 2016 16:12:13 C:\Python27\lib\site-packages\werkzeug-0.10.4-py2.7.egg\werkzeug\_internal.py[line:87] INFO  * Restarting with stat
Mon, 07 Mar 2016 16:13:33 C:\Python27\lib\site-packages\werkzeug-0.10.4-py2.7.egg\werkzeug\_internal.py[line:87] INFO  * Detected change in 'E:\\mana_api\\mana_api\\models.py', reloading
Mon, 07 Mar 2016 16:13:33 C:\Python27\lib\site-packages\werkzeug-0.10.4-py2.7.egg\werkzeug\_internal.py[line:87] INFO  * Restarting with stat
Mon, 07 Mar 2016 16:13:54 C:\Python27\lib\site-packages\werkzeug-0.10.4-py2.7.egg\werkzeug\_internal.py[line:87] INFO  * Detected change in 'E:\\mana_api\\mana_api\\models.py', reloading
Mon, 07 Mar 2016 16:13:54 C:\Python27\lib\site-packages\werkzeug-0.10.4-py2.7.egg\werkzeug\_internal.py[line:87] INFO  * Restarting with stat
Mon, 07 Mar 2016 16:14:06 C:\Python27\lib\site-packages\werkzeug-0.10.4-py2.7.egg\werkzeug\_internal.py[line:87] INFO  * Detected change in 'E:\\mana_api\\mana_api\\models.py', reloading
Mon, 07 Mar 2016 16:14:06 C:\Python27\lib\site-packages\werkzeug-0.10.4-py2.7.egg\werkzeug\_internal.py[line:87] INFO  * Restarting with stat
Mon, 07 Mar 2016 16:14:54 C:\Python27\lib\site-packages\werkzeug-0.10.4-py2.7.egg\werkzeug\_internal.py[line:87] INFO  * Detected change in 'E:\\mana_api\\mana_api\\models.py', reloading
Mon, 07 Mar 2016 16:14:54 C:\Python27\lib\site-packages\werkzeug-0.10.4-py2.7.egg\werkzeug\_internal.py[line:87] INFO  * Restarting with stat
Mon, 07 Mar 2016 16:15:06 C:\Python27\lib\site-packages\werkzeug-0.10.4-py2.7.egg\werkzeug\_internal.py[line:87] INFO  * Detected change in 'E:\\mana_api\\mana_api\\models.py', reloading
Mon, 07 Mar 2016 16:15:06 C:\Python27\lib\site-packages\werkzeug-0.10.4-py2.7.egg\werkzeug\_internal.py[line:87] INFO  * Restarting with stat
Mon, 07 Mar 2016 16:16:21 C:\Python27\lib\site-packages\werkzeug-0.10.4-py2.7.egg\werkzeug\_internal.py[line:87] INFO 192.168.39.170 - - [07/Mar/2016 16:16:21] "GET /mana_api/pm_bill_detail?tenant_id=666 HTTP/1.1" 400 -
Mon, 07 Mar 2016 16:16:52 C:\Python27\lib\site-packages\werkzeug-0.10.4-py2.7.egg\werkzeug\_internal.py[line:87] INFO 192.168.39.170 - - [07/Mar/2016 16:16:52] "GET /mana_api/pm_bill_tenant_id=666 HTTP/1.1" 404 -
Mon, 07 Mar 2016 16:16:56 C:\Python27\lib\site-packages\werkzeug-0.10.4-py2.7.egg\werkzeug\_internal.py[line:87] INFO 192.168.39.170 - - [07/Mar/2016 16:16:56] "GET /mana_api/pm_bill_tenant_id=666 HTTP/1.1" 404 -
Mon, 07 Mar 2016 16:17:01 C:\Python27\lib\site-packages\werkzeug-0.10.4-py2.7.egg\werkzeug\_internal.py[line:87] INFO 192.168.39.170 - - [07/Mar/2016 16:17:01] "GET /mana_api/pm_bill=tenant_id=666 HTTP/1.1" 404 -
Mon, 07 Mar 2016 16:17:04 C:\Python27\lib\site-packages\werkzeug-0.10.4-py2.7.egg\werkzeug\_internal.py[line:87] INFO 192.168.39.170 - - [07/Mar/2016 16:17:04] "GET /mana_api/pm_bill?tenant_id=666 HTTP/1.1" 403 -
Mon, 07 Mar 2016 16:17:54 E:\mana_api\mana_api\api\pm_mana.py[line:110] INFO Request: get pm accounts tenant_id => 74d4bda6aa1c466d8cb1f2b8eac79567 
Mon, 07 Mar 2016 16:17:54 C:\Python27\lib\site-packages\werkzeug-0.10.4-py2.7.egg\werkzeug\_internal.py[line:87] INFO 192.168.39.170 - - [07/Mar/2016 16:17:54] "GET /mana_api/pm_bill?tenant_id=74d4bda6aa1c466d8cb1f2b8eac79567 HTTP/1.1" 200 -
Mon, 07 Mar 2016 16:22:51 C:\Python27\lib\site-packages\werkzeug-0.10.4-py2.7.egg\werkzeug\_internal.py[line:87] INFO  * Detected change in 'E:\\mana_api\\mana_api\\apiUtil.py', reloading
Mon, 07 Mar 2016 16:22:51 C:\Python27\lib\site-packages\werkzeug-0.10.4-py2.7.egg\werkzeug\_internal.py[line:87] INFO  * Restarting with stat
Mon, 07 Mar 2016 16:22:53 E:\mana_api\mana_api\api\pm_mana.py[line:110] INFO Request: get pm accounts tenant_id => 74d4bda6aa1c466d8cb1f2b8eac79567 
Mon, 07 Mar 2016 16:22:54 C:\Python27\lib\site-packages\werkzeug-0.10.4-py2.7.egg\werkzeug\_internal.py[line:87] INFO 192.168.39.170 - - [07/Mar/2016 16:22:54] "GET /mana_api/pm_bill?tenant_id=74d4bda6aa1c466d8cb1f2b8eac79567 HTTP/1.1" 200 -
Mon, 07 Mar 2016 16:23:36 C:\Python27\lib\site-packages\werkzeug-0.10.4-py2.7.egg\werkzeug\_internal.py[line:87] INFO  * Detected change in 'E:\\mana_api\\mana_api\\apiUtil.py', reloading
Mon, 07 Mar 2016 16:23:36 C:\Python27\lib\site-packages\werkzeug-0.10.4-py2.7.egg\werkzeug\_internal.py[line:87] INFO  * Restarting with stat
Mon, 07 Mar 2016 16:25:47 C:\Python27\lib\site-packages\werkzeug-0.10.4-py2.7.egg\werkzeug\_internal.py[line:87] INFO  * Detected change in 'E:\\mana_api\\mana_api\\apiUtil.py', reloading
Mon, 07 Mar 2016 16:25:47 C:\Python27\lib\site-packages\werkzeug-0.10.4-py2.7.egg\werkzeug\_internal.py[line:87] INFO  * Restarting with stat
Mon, 07 Mar 2016 16:45:32 C:\Python27\lib\site-packages\werkzeug-0.10.4-py2.7.egg\werkzeug\_internal.py[line:87] INFO  * Detected change in 'E:\\mana_api\\mana_api\\apiUtil.py', reloading
Mon, 07 Mar 2016 16:45:32 C:\Python27\lib\site-packages\werkzeug-0.10.4-py2.7.egg\werkzeug\_internal.py[line:87] INFO  * Restarting with stat
Mon, 07 Mar 2016 16:45:34 C:\Python27\lib\site-packages\werkzeug-0.10.4-py2.7.egg\werkzeug\_internal.py[line:87] INFO  * Detected change in 'E:\\mana_api\\mana_api\\apiUtil.py', reloading
Mon, 07 Mar 2016 16:45:34 C:\Python27\lib\site-packages\werkzeug-0.10.4-py2.7.egg\werkzeug\_internal.py[line:87] INFO  * Restarting with stat
Mon, 07 Mar 2016 16:47:37 C:\Python27\lib\site-packages\werkzeug-0.10.4-py2.7.egg\werkzeug\_internal.py[line:87] INFO  * Detected change in 'E:\\mana_api\\mana_api\\apiUtil.py', reloading
Mon, 07 Mar 2016 16:47:37 C:\Python27\lib\site-packages\werkzeug-0.10.4-py2.7.egg\werkzeug\_internal.py[line:87] INFO  * Restarting with stat
Mon, 07 Mar 2016 16:47:40 E:\mana_api\mana_api\api\pm_mana.py[line:110] INFO Request: get pm accounts tenant_id => 74d4bda6aa1c466d8cb1f2b8eac79567 
Mon, 07 Mar 2016 16:47:40 E:\mana_api\mana_api\api\pm_mana.py[line:116] ERROR Error with get pm_accounts
Traceback (most recent call last):
  File "E:\mana_api\mana_api\api\pm_mana.py", line 113, in pm_bill
    result = get_pm_accounts(tenant_id)
  File "E:\mana_api\mana_api\apiUtil.py", line 272, in get_pm_accounts
    enpense_virtual.tenant_id == tenant_id
AttributeError: type object 'enpense_virtual' has no attribute 'tenant_id'
Mon, 07 Mar 2016 16:47:40 C:\Python27\lib\site-packages\werkzeug-0.10.4-py2.7.egg\werkzeug\_internal.py[line:87] INFO 192.168.39.170 - - [07/Mar/2016 16:47:40] "GET /mana_api/pm_bill?tenant_id=74d4bda6aa1c466d8cb1f2b8eac79567 HTTP/1.1" 400 -
Mon, 07 Mar 2016 16:48:13 C:\Python27\lib\site-packages\werkzeug-0.10.4-py2.7.egg\werkzeug\_internal.py[line:87] INFO  * Detected change in 'E:\\mana_api\\mana_api\\apiUtil.py', reloading
Mon, 07 Mar 2016 16:48:13 C:\Python27\lib\site-packages\werkzeug-0.10.4-py2.7.egg\werkzeug\_internal.py[line:87] INFO  * Restarting with stat
Mon, 07 Mar 2016 16:48:38 C:\Python27\lib\site-packages\werkzeug-0.10.4-py2.7.egg\werkzeug\_internal.py[line:87] INFO  * Detected change in 'E:\\mana_api\\mana_api\\apiUtil.py', reloading
Mon, 07 Mar 2016 16:48:38 C:\Python27\lib\site-packages\werkzeug-0.10.4-py2.7.egg\werkzeug\_internal.py[line:87] INFO  * Restarting with stat
Mon, 07 Mar 2016 16:54:52 C:\Python27\lib\site-packages\werkzeug-0.10.4-py2.7.egg\werkzeug\_internal.py[line:87] INFO  * Detected change in 'E:\\mana_api\\mana_api\\apiUtil.py', reloading
Mon, 07 Mar 2016 16:54:52 C:\Python27\lib\site-packages\werkzeug-0.10.4-py2.7.egg\werkzeug\_internal.py[line:87] INFO  * Restarting with stat
Mon, 07 Mar 2016 16:55:06 C:\Python27\lib\site-packages\werkzeug-0.10.4-py2.7.egg\werkzeug\_internal.py[line:87] INFO  * Detected change in 'E:\\mana_api\\mana_api\\apiUtil.py', reloading
Mon, 07 Mar 2016 16:55:06 C:\Python27\lib\site-packages\werkzeug-0.10.4-py2.7.egg\werkzeug\_internal.py[line:87] INFO  * Restarting with stat
Mon, 07 Mar 2016 16:55:34 C:\Python27\lib\site-packages\werkzeug-0.10.4-py2.7.egg\werkzeug\_internal.py[line:87] INFO  * Detected change in 'E:\\mana_api\\mana_api\\apiUtil.py', reloading
Mon, 07 Mar 2016 16:55:34 C:\Python27\lib\site-packages\werkzeug-0.10.4-py2.7.egg\werkzeug\_internal.py[line:87] INFO  * Restarting with stat
Mon, 07 Mar 2016 16:59:43 C:\Python27\lib\site-packages\werkzeug-0.10.4-py2.7.egg\werkzeug\_internal.py[line:87] INFO  * Detected change in 'E:\\mana_api\\mana_api\\apiUtil.py', reloading
Mon, 07 Mar 2016 16:59:43 C:\Python27\lib\site-packages\werkzeug-0.10.4-py2.7.egg\werkzeug\_internal.py[line:87] INFO  * Restarting with stat
Mon, 07 Mar 2016 17:03:39 C:\Python27\lib\site-packages\werkzeug-0.10.4-py2.7.egg\werkzeug\_internal.py[line:87] INFO  * Detected change in 'E:\\mana_api\\mana_api\\apiUtil.py', reloading
Mon, 07 Mar 2016 17:03:39 C:\Python27\lib\site-packages\werkzeug-0.10.4-py2.7.egg\werkzeug\_internal.py[line:87] INFO  * Restarting with stat
Mon, 07 Mar 2016 17:21:17 C:\Python27\lib\site-packages\werkzeug-0.10.4-py2.7.egg\werkzeug\_internal.py[line:87] INFO  * Running on http://0.0.0.0:8181/ (Press CTRL+C to quit)
Mon, 07 Mar 2016 17:21:17 C:\Python27\lib\site-packages\werkzeug-0.10.4-py2.7.egg\werkzeug\_internal.py[line:87] INFO  * Restarting with stat
Mon, 07 Mar 2016 17:21:20 E:\mana_api\mana_api\api\pm_mana.py[line:110] INFO Request: get pm accounts tenant_id => 74d4bda6aa1c466d8cb1f2b8eac79567 
Mon, 07 Mar 2016 17:21:20 E:\mana_api\mana_api\api\pm_mana.py[line:116] ERROR Error with get pm_accounts
Traceback (most recent call last):
  File "E:\mana_api\mana_api\api\pm_mana.py", line 113, in pm_bill
    result = get_pm_accounts(tenant_id)
  File "E:\mana_api\mana_api\apiUtil.py", line 273, in get_pm_accounts
    enpense_virtual.projectID == tenant_id
  File "C:\Python27\lib\site-packages\sqlalchemy\orm\query.py", line 2423, in all
    return list(self)
  File "C:\Python27\lib\site-packages\sqlalchemy\orm\query.py", line 2571, in __iter__
    return self._execute_and_instances(context)
  File "C:\Python27\lib\site-packages\sqlalchemy\orm\query.py", line 2586, in _execute_and_instances
    result = conn.execute(querycontext.statement, self._params)
  File "C:\Python27\lib\site-packages\sqlalchemy\engine\base.py", line 914, in execute
    return meth(self, multiparams, params)
  File "C:\Python27\lib\site-packages\sqlalchemy\sql\elements.py", line 323, in _execute_on_connection
    return connection._execute_clauseelement(self, multiparams, params)
  File "C:\Python27\lib\site-packages\sqlalchemy\engine\base.py", line 1010, in _execute_clauseelement
    compiled_sql, distilled_params
  File "C:\Python27\lib\site-packages\sqlalchemy\engine\base.py", line 1146, in _execute_context
    context)
  File "C:\Python27\lib\site-packages\sqlalchemy\engine\base.py", line 1341, in _handle_dbapi_exception
    exc_info
  File "C:\Python27\lib\site-packages\sqlalchemy\util\compat.py", line 199, in raise_from_cause
    reraise(type(exception), exception, tb=exc_tb)
  File "C:\Python27\lib\site-packages\sqlalchemy\engine\base.py", line 1139, in _execute_context
    context)
  File "C:\Python27\lib\site-packages\sqlalchemy\engine\default.py", line 450, in do_execute
    cursor.execute(statement, parameters)
  File "C:\Python27\lib\site-packages\MySQLdb\cursors.py", line 174, in execute
    self.errorhandler(self, exc, value)
  File "C:\Python27\lib\site-packages\MySQLdb\connections.py", line 36, in defaulterrorhandler
    raise errorclass, errorvalue
ProgrammingError: (_mysql_exceptions.ProgrammingError) (1146, "Table 'cloud.enpense_virtual' doesn't exist") [SQL: u'SELECT enpense_virtual.id AS enpense_virtual_id, enpense_virtual.`locationID` AS `enpense_virtual_locationID`, enpense_virtual.`projectID` AS `enpense_virtual_projectID`, enpense_virtual.`serverID` AS `enpense_virtual_serverID`, enpense_virtual.year AS enpense_virtual_year, enpense_virtual.month AS enpense_virtual_month, enpense_virtual.day AS enpense_virtual_day, enpense_virtual.value AS enpense_virtual_value, enpense_virtual.`personID` AS `enpense_virtual_personID`, enpense_virtual.display_name AS enpense_virtual_display_name \nFROM enpense_virtual \nWHERE enpense_virtual.`projectID` = %s'] [parameters: ('74d4bda6aa1c466d8cb1f2b8eac79567',)]
Mon, 07 Mar 2016 17:21:20 C:\Python27\lib\site-packages\werkzeug-0.10.4-py2.7.egg\werkzeug\_internal.py[line:87] INFO 192.168.39.170 - - [07/Mar/2016 17:21:20] "GET /mana_api/pm_bill?tenant_id=74d4bda6aa1c466d8cb1f2b8eac79567 HTTP/1.1" 400 -
Mon, 07 Mar 2016 17:21:30 E:\mana_api\mana_api\api\pm_mana.py[line:110] INFO Request: get pm accounts tenant_id => 74d4bda6aa1c466d8cb1f2b8eac79567 
Mon, 07 Mar 2016 17:21:30 E:\mana_api\mana_api\api\pm_mana.py[line:116] ERROR Error with get pm_accounts
Traceback (most recent call last):
  File "E:\mana_api\mana_api\api\pm_mana.py", line 113, in pm_bill
    result = get_pm_accounts(tenant_id)
  File "E:\mana_api\mana_api\apiUtil.py", line 273, in get_pm_accounts
    enpense_virtual.projectID == tenant_id
  File "C:\Python27\lib\site-packages\sqlalchemy\orm\query.py", line 2423, in all
    return list(self)
  File "C:\Python27\lib\site-packages\sqlalchemy\orm\query.py", line 2571, in __iter__
    return self._execute_and_instances(context)
  File "C:\Python27\lib\site-packages\sqlalchemy\orm\query.py", line 2586, in _execute_and_instances
    result = conn.execute(querycontext.statement, self._params)
  File "C:\Python27\lib\site-packages\sqlalchemy\engine\base.py", line 914, in execute
    return meth(self, multiparams, params)
  File "C:\Python27\lib\site-packages\sqlalchemy\sql\elements.py", line 323, in _execute_on_connection
    return connection._execute_clauseelement(self, multiparams, params)
  File "C:\Python27\lib\site-packages\sqlalchemy\engine\base.py", line 1010, in _execute_clauseelement
    compiled_sql, distilled_params
  File "C:\Python27\lib\site-packages\sqlalchemy\engine\base.py", line 1146, in _execute_context
    context)
  File "C:\Python27\lib\site-packages\sqlalchemy\engine\base.py", line 1341, in _handle_dbapi_exception
    exc_info
  File "C:\Python27\lib\site-packages\sqlalchemy\util\compat.py", line 199, in raise_from_cause
    reraise(type(exception), exception, tb=exc_tb)
  File "C:\Python27\lib\site-packages\sqlalchemy\engine\base.py", line 1139, in _execute_context
    context)
  File "C:\Python27\lib\site-packages\sqlalchemy\engine\default.py", line 450, in do_execute
    cursor.execute(statement, parameters)
  File "C:\Python27\lib\site-packages\MySQLdb\cursors.py", line 174, in execute
    self.errorhandler(self, exc, value)
  File "C:\Python27\lib\site-packages\MySQLdb\connections.py", line 36, in defaulterrorhandler
    raise errorclass, errorvalue
ProgrammingError: (_mysql_exceptions.ProgrammingError) (1146, "Table 'cloud.enpense_virtual' doesn't exist") [SQL: u'SELECT enpense_virtual.id AS enpense_virtual_id, enpense_virtual.`locationID` AS `enpense_virtual_locationID`, enpense_virtual.`projectID` AS `enpense_virtual_projectID`, enpense_virtual.`serverID` AS `enpense_virtual_serverID`, enpense_virtual.year AS enpense_virtual_year, enpense_virtual.month AS enpense_virtual_month, enpense_virtual.day AS enpense_virtual_day, enpense_virtual.value AS enpense_virtual_value, enpense_virtual.`personID` AS `enpense_virtual_personID`, enpense_virtual.display_name AS enpense_virtual_display_name \nFROM enpense_virtual \nWHERE enpense_virtual.`projectID` = %s'] [parameters: ('74d4bda6aa1c466d8cb1f2b8eac79567',)]
Mon, 07 Mar 2016 17:21:30 C:\Python27\lib\site-packages\werkzeug-0.10.4-py2.7.egg\werkzeug\_internal.py[line:87] INFO 192.168.39.170 - - [07/Mar/2016 17:21:30] "GET /mana_api/pm_bill?tenant_id=74d4bda6aa1c466d8cb1f2b8eac79567 HTTP/1.1" 400 -
Mon, 07 Mar 2016 17:22:18 C:\Python27\lib\site-packages\werkzeug-0.10.4-py2.7.egg\werkzeug\_internal.py[line:87] INFO  * Detected change in 'E:\\mana_api\\mana_api\\models.py', reloading
Mon, 07 Mar 2016 17:22:18 C:\Python27\lib\site-packages\werkzeug-0.10.4-py2.7.egg\werkzeug\_internal.py[line:87] INFO  * Restarting with stat
Mon, 07 Mar 2016 17:22:57 C:\Python27\lib\site-packages\werkzeug-0.10.4-py2.7.egg\werkzeug\_internal.py[line:87] INFO  * Running on http://0.0.0.0:8181/ (Press CTRL+C to quit)
Mon, 07 Mar 2016 17:22:57 C:\Python27\lib\site-packages\werkzeug-0.10.4-py2.7.egg\werkzeug\_internal.py[line:87] INFO  * Restarting with stat
Mon, 07 Mar 2016 17:22:59 E:\mana_api\mana_api\api\pm_mana.py[line:110] INFO Request: get pm accounts tenant_id => 74d4bda6aa1c466d8cb1f2b8eac79567 
Mon, 07 Mar 2016 17:22:59 E:\mana_api\mana_api\api\pm_mana.py[line:116] ERROR Error with get pm_accounts
Traceback (most recent call last):
  File "E:\mana_api\mana_api\api\pm_mana.py", line 113, in pm_bill
    result = get_pm_accounts(tenant_id)
  File "E:\mana_api\mana_api\apiUtil.py", line 273, in get_pm_accounts
    expense_virtual.projectID == tenant_id
  File "C:\Python27\lib\site-packages\sqlalchemy\orm\query.py", line 2423, in all
    return list(self)
  File "C:\Python27\lib\site-packages\sqlalchemy\orm\query.py", line 2571, in __iter__
    return self._execute_and_instances(context)
  File "C:\Python27\lib\site-packages\sqlalchemy\orm\query.py", line 2586, in _execute_and_instances
    result = conn.execute(querycontext.statement, self._params)
  File "C:\Python27\lib\site-packages\sqlalchemy\engine\base.py", line 914, in execute
    return meth(self, multiparams, params)
  File "C:\Python27\lib\site-packages\sqlalchemy\sql\elements.py", line 323, in _execute_on_connection
    return connection._execute_clauseelement(self, multiparams, params)
  File "C:\Python27\lib\site-packages\sqlalchemy\engine\base.py", line 1010, in _execute_clauseelement
    compiled_sql, distilled_params
  File "C:\Python27\lib\site-packages\sqlalchemy\engine\base.py", line 1146, in _execute_context
    context)
  File "C:\Python27\lib\site-packages\sqlalchemy\engine\base.py", line 1341, in _handle_dbapi_exception
    exc_info
  File "C:\Python27\lib\site-packages\sqlalchemy\util\compat.py", line 199, in raise_from_cause
    reraise(type(exception), exception, tb=exc_tb)
  File "C:\Python27\lib\site-packages\sqlalchemy\engine\base.py", line 1139, in _execute_context
    context)
  File "C:\Python27\lib\site-packages\sqlalchemy\engine\default.py", line 450, in do_execute
    cursor.execute(statement, parameters)
  File "C:\Python27\lib\site-packages\MySQLdb\cursors.py", line 174, in execute
    self.errorhandler(self, exc, value)
  File "C:\Python27\lib\site-packages\MySQLdb\connections.py", line 36, in defaulterrorhandler
    raise errorclass, errorvalue
OperationalError: (_mysql_exceptions.OperationalError) (1054, "Unknown column 'expense_virtual.id' in 'field list'") [SQL: u'SELECT expense_virtual.id AS expense_virtual_id, expense_virtual.`locationID` AS `expense_virtual_locationID`, expense_virtual.`projectID` AS `expense_virtual_projectID`, expense_virtual.`serverID` AS `expense_virtual_serverID`, expense_virtual.year AS expense_virtual_year, expense_virtual.month AS expense_virtual_month, expense_virtual.day AS expense_virtual_day, expense_virtual.value AS expense_virtual_value, expense_virtual.`personID` AS `expense_virtual_personID`, expense_virtual.display_name AS expense_virtual_display_name \nFROM expense_virtual \nWHERE expense_virtual.`projectID` = %s'] [parameters: ('74d4bda6aa1c466d8cb1f2b8eac79567',)]
Mon, 07 Mar 2016 17:22:59 C:\Python27\lib\site-packages\werkzeug-0.10.4-py2.7.egg\werkzeug\_internal.py[line:87] INFO 192.168.39.170 - - [07/Mar/2016 17:22:59] "GET /mana_api/pm_bill?tenant_id=74d4bda6aa1c466d8cb1f2b8eac79567 HTTP/1.1" 400 -
Mon, 07 Mar 2016 17:23:06 E:\mana_api\mana_api\api\pm_mana.py[line:110] INFO Request: get pm accounts tenant_id => 74d4bda6aa1c466d8cb1f2b8eac79567 
Mon, 07 Mar 2016 17:23:06 E:\mana_api\mana_api\api\pm_mana.py[line:116] ERROR Error with get pm_accounts
Traceback (most recent call last):
  File "E:\mana_api\mana_api\api\pm_mana.py", line 113, in pm_bill
    result = get_pm_accounts(tenant_id)
  File "E:\mana_api\mana_api\apiUtil.py", line 273, in get_pm_accounts
    expense_virtual.projectID == tenant_id
  File "C:\Python27\lib\site-packages\sqlalchemy\orm\query.py", line 2423, in all
    return list(self)
  File "C:\Python27\lib\site-packages\sqlalchemy\orm\query.py", line 2571, in __iter__
    return self._execute_and_instances(context)
  File "C:\Python27\lib\site-packages\sqlalchemy\orm\query.py", line 2586, in _execute_and_instances
    result = conn.execute(querycontext.statement, self._params)
  File "C:\Python27\lib\site-packages\sqlalchemy\engine\base.py", line 914, in execute
    return meth(self, multiparams, params)
  File "C:\Python27\lib\site-packages\sqlalchemy\sql\elements.py", line 323, in _execute_on_connection
    return connection._execute_clauseelement(self, multiparams, params)
  File "C:\Python27\lib\site-packages\sqlalchemy\engine\base.py", line 1010, in _execute_clauseelement
    compiled_sql, distilled_params
  File "C:\Python27\lib\site-packages\sqlalchemy\engine\base.py", line 1146, in _execute_context
    context)
  File "C:\Python27\lib\site-packages\sqlalchemy\engine\base.py", line 1341, in _handle_dbapi_exception
    exc_info
  File "C:\Python27\lib\site-packages\sqlalchemy\util\compat.py", line 199, in raise_from_cause
    reraise(type(exception), exception, tb=exc_tb)
  File "C:\Python27\lib\site-packages\sqlalchemy\engine\base.py", line 1139, in _execute_context
    context)
  File "C:\Python27\lib\site-packages\sqlalchemy\engine\default.py", line 450, in do_execute
    cursor.execute(statement, parameters)
  File "C:\Python27\lib\site-packages\MySQLdb\cursors.py", line 174, in execute
    self.errorhandler(self, exc, value)
  File "C:\Python27\lib\site-packages\MySQLdb\connections.py", line 36, in defaulterrorhandler
    raise errorclass, errorvalue
OperationalError: (_mysql_exceptions.OperationalError) (1054, "Unknown column 'expense_virtual.id' in 'field list'") [SQL: u'SELECT expense_virtual.id AS expense_virtual_id, expense_virtual.`locationID` AS `expense_virtual_locationID`, expense_virtual.`projectID` AS `expense_virtual_projectID`, expense_virtual.`serverID` AS `expense_virtual_serverID`, expense_virtual.year AS expense_virtual_year, expense_virtual.month AS expense_virtual_month, expense_virtual.day AS expense_virtual_day, expense_virtual.value AS expense_virtual_value, expense_virtual.`personID` AS `expense_virtual_personID`, expense_virtual.display_name AS expense_virtual_display_name \nFROM expense_virtual \nWHERE expense_virtual.`projectID` = %s'] [parameters: ('74d4bda6aa1c466d8cb1f2b8eac79567',)]
Mon, 07 Mar 2016 17:23:06 C:\Python27\lib\site-packages\werkzeug-0.10.4-py2.7.egg\werkzeug\_internal.py[line:87] INFO 192.168.39.170 - - [07/Mar/2016 17:23:06] "GET /mana_api/pm_bill?tenant_id=74d4bda6aa1c466d8cb1f2b8eac79567 HTTP/1.1" 400 -
Mon, 07 Mar 2016 17:23:27 C:\Python27\lib\site-packages\werkzeug-0.10.4-py2.7.egg\werkzeug\_internal.py[line:87] INFO  * Detected change in 'E:\\mana_api\\mana_api\\models.py', reloading
Mon, 07 Mar 2016 17:23:27 C:\Python27\lib\site-packages\werkzeug-0.10.4-py2.7.egg\werkzeug\_internal.py[line:87] INFO  * Restarting with stat
Mon, 07 Mar 2016 17:26:49 C:\Python27\lib\site-packages\werkzeug-0.10.4-py2.7.egg\werkzeug\_internal.py[line:87] INFO  * Running on http://0.0.0.0:8181/ (Press CTRL+C to quit)
Mon, 07 Mar 2016 17:26:49 C:\Python27\lib\site-packages\werkzeug-0.10.4-py2.7.egg\werkzeug\_internal.py[line:87] INFO  * Restarting with stat
Mon, 07 Mar 2016 17:26:52 E:\mana_api\mana_api\api\pm_mana.py[line:110] INFO Request: get pm accounts tenant_id => 74d4bda6aa1c466d8cb1f2b8eac79567 
Mon, 07 Mar 2016 17:26:52 E:\mana_api\mana_api\api\pm_mana.py[line:116] ERROR Error with get pm_accounts
Traceback (most recent call last):
  File "E:\mana_api\mana_api\api\pm_mana.py", line 113, in pm_bill
    result = get_pm_accounts(tenant_id)
  File "E:\mana_api\mana_api\apiUtil.py", line 273, in get_pm_accounts
    expense_virtual.projectID == tenant_id
  File "C:\Python27\lib\site-packages\sqlalchemy\orm\query.py", line 2423, in all
    return list(self)
  File "C:\Python27\lib\site-packages\sqlalchemy\orm\query.py", line 2571, in __iter__
    return self._execute_and_instances(context)
  File "C:\Python27\lib\site-packages\sqlalchemy\orm\query.py", line 2586, in _execute_and_instances
    result = conn.execute(querycontext.statement, self._params)
  File "C:\Python27\lib\site-packages\sqlalchemy\engine\base.py", line 914, in execute
    return meth(self, multiparams, params)
  File "C:\Python27\lib\site-packages\sqlalchemy\sql\elements.py", line 323, in _execute_on_connection
    return connection._execute_clauseelement(self, multiparams, params)
  File "C:\Python27\lib\site-packages\sqlalchemy\engine\base.py", line 1010, in _execute_clauseelement
    compiled_sql, distilled_params
  File "C:\Python27\lib\site-packages\sqlalchemy\engine\base.py", line 1146, in _execute_context
    context)
  File "C:\Python27\lib\site-packages\sqlalchemy\engine\base.py", line 1341, in _handle_dbapi_exception
    exc_info
  File "C:\Python27\lib\site-packages\sqlalchemy\util\compat.py", line 199, in raise_from_cause
    reraise(type(exception), exception, tb=exc_tb)
  File "C:\Python27\lib\site-packages\sqlalchemy\engine\base.py", line 1139, in _execute_context
    context)
  File "C:\Python27\lib\site-packages\sqlalchemy\engine\default.py", line 450, in do_execute
    cursor.execute(statement, parameters)
  File "C:\Python27\lib\site-packages\MySQLdb\cursors.py", line 174, in execute
    self.errorhandler(self, exc, value)
  File "C:\Python27\lib\site-packages\MySQLdb\connections.py", line 36, in defaulterrorhandler
    raise errorclass, errorvalue
OperationalError: (_mysql_exceptions.OperationalError) (1054, "Unknown column 'expense_virtual.id' in 'field list'") [SQL: u'SELECT expense_virtual.id AS expense_virtual_id, expense_virtual.`locationID` AS `expense_virtual_locationID`, expense_virtual.`projectID` AS `expense_virtual_projectID`, expense_virtual.`serverID` AS `expense_virtual_serverID`, expense_virtual.year AS expense_virtual_year, expense_virtual.month AS expense_virtual_month, expense_virtual.day AS expense_virtual_day, expense_virtual.value AS expense_virtual_value, expense_virtual.`personID` AS `expense_virtual_personID`, expense_virtual.display_name AS expense_virtual_display_name \nFROM expense_virtual \nWHERE expense_virtual.`projectID` = %s'] [parameters: ('74d4bda6aa1c466d8cb1f2b8eac79567',)]
Mon, 07 Mar 2016 17:26:52 C:\Python27\lib\site-packages\werkzeug-0.10.4-py2.7.egg\werkzeug\_internal.py[line:87] INFO 192.168.39.170 - - [07/Mar/2016 17:26:52] "GET /mana_api/pm_bill?tenant_id=74d4bda6aa1c466d8cb1f2b8eac79567 HTTP/1.1" 400 -
























Mon, 07 Mar 2016 17:27:05 E:\mana_api\mana_api\api\pm_mana.py[line:110] INFO Request: get pm accounts tenant_id => 74d4bda6aa1c466d8cb1f2b8eac79567 
Mon, 07 Mar 2016 17:27:05 E:\mana_api\mana_api\api\pm_mana.py[line:116] ERROR Error with get pm_accounts
Traceback (most recent call last):
  File "E:\mana_api\mana_api\api\pm_mana.py", line 113, in pm_bill
    result = get_pm_accounts(tenant_id)
  File "E:\mana_api\mana_api\apiUtil.py", line 273, in get_pm_accounts
    expense_virtual.projectID == tenant_id
  File "C:\Python27\lib\site-packages\sqlalchemy\orm\query.py", line 2423, in all
    return list(self)
  File "C:\Python27\lib\site-packages\sqlalchemy\orm\query.py", line 2571, in __iter__
    return self._execute_and_instances(context)
  File "C:\Python27\lib\site-packages\sqlalchemy\orm\query.py", line 2586, in _execute_and_instances
    result = conn.execute(querycontext.statement, self._params)
  File "C:\Python27\lib\site-packages\sqlalchemy\engine\base.py", line 914, in execute
    return meth(self, multiparams, params)
  File "C:\Python27\lib\site-packages\sqlalchemy\sql\elements.py", line 323, in _execute_on_connection
    return connection._execute_clauseelement(self, multiparams, params)
  File "C:\Python27\lib\site-packages\sqlalchemy\engine\base.py", line 1010, in _execute_clauseelement
    compiled_sql, distilled_params
  File "C:\Python27\lib\site-packages\sqlalchemy\engine\base.py", line 1146, in _execute_context
    context)
  File "C:\Python27\lib\site-packages\sqlalchemy\engine\base.py", line 1341, in _handle_dbapi_exception
    exc_info
  File "C:\Python27\lib\site-packages\sqlalchemy\util\compat.py", line 199, in raise_from_cause
    reraise(type(exception), exception, tb=exc_tb)
  File "C:\Python27\lib\site-packages\sqlalchemy\engine\base.py", line 1139, in _execute_context
    context)
  File "C:\Python27\lib\site-packages\sqlalchemy\engine\default.py", line 450, in do_execute
    cursor.execute(statement, parameters)
  File "C:\Python27\lib\site-packages\MySQLdb\cursors.py", line 174, in execute
    self.errorhandler(self, exc, value)
  File "C:\Python27\lib\site-packages\MySQLdb\connections.py", line 36, in defaulterrorhandler
    raise errorclass, errorvalue
OperationalError: (_mysql_exceptions.OperationalError) (1054, "Unknown column 'expense_virtual.id' in 'field list'") [SQL: u'SELECT expense_virtual.id AS expense_virtual_id, expense_virtual.`locationID` AS `expense_virtual_locationID`, expense_virtual.`projectID` AS `expense_virtual_projectID`, expense_virtual.`serverID` AS `expense_virtual_serverID`, expense_virtual.year AS expense_virtual_year, expense_virtual.month AS expense_virtual_month, expense_virtual.day AS expense_virtual_day, expense_virtual.value AS expense_virtual_value, expense_virtual.`personID` AS `expense_virtual_personID`, expense_virtual.display_name AS expense_virtual_display_name \nFROM expense_virtual \nWHERE expense_virtual.`projectID` = %s'] [parameters: ('74d4bda6aa1c466d8cb1f2b8eac79567',)]
Mon, 07 Mar 2016 17:27:05 C:\Python27\lib\site-packages\werkzeug-0.10.4-py2.7.egg\werkzeug\_internal.py[line:87] INFO 192.168.39.170 - - [07/Mar/2016 17:27:05] "GET /mana_api/pm_bill?tenant_id=74d4bda6aa1c466d8cb1f2b8eac79567 HTTP/1.1" 400 -
Mon, 07 Mar 2016 17:31:02 E:\mana_api\mana_api\api\pm_mana.py[line:110] INFO Request: get pm accounts tenant_id => 74d4bda6aa1c466d8cb1f2b8eac79567 
Mon, 07 Mar 2016 17:31:02 C:\Python27\lib\site-packages\werkzeug-0.10.4-py2.7.egg\werkzeug\_internal.py[line:87] INFO 192.168.39.170 - - [07/Mar/2016 17:31:02] "GET /mana_api/pm_bill?tenant_id=74d4bda6aa1c466d8cb1f2b8eac79567 HTTP/1.1" 200 -










Mon, 07 Mar 2016 17:35:06 E:\mana_api\mana_api\api\pm_mana.py[line:110] INFO Request: get pm accounts tenant_id => 74d4bda6aa1c466d8cb1f2b8eac79567 
Mon, 07 Mar 2016 17:35:06 C:\Python27\lib\site-packages\werkzeug-0.10.4-py2.7.egg\werkzeug\_internal.py[line:87] INFO 192.168.39.170 - - [07/Mar/2016 17:35:06] "GET /mana_api/pm_bill?tenant_id=74d4bda6aa1c466d8cb1f2b8eac79567 HTTP/1.1" 200 -
Mon, 07 Mar 2016 17:39:37 C:\Python27\lib\site-packages\werkzeug-0.10.4-py2.7.egg\werkzeug\_internal.py[line:87] INFO  * Detected change in 'E:\\mana_api\\mana_api\\apiUtil.py', reloading
Mon, 07 Mar 2016 17:39:37 C:\Python27\lib\site-packages\werkzeug-0.10.4-py2.7.egg\werkzeug\_internal.py[line:87] INFO  * Restarting with stat
Mon, 07 Mar 2016 17:39:40 E:\mana_api\mana_api\api\pm_mana.py[line:110] INFO Request: get pm accounts tenant_id => 74d4bda6aa1c466d8cb1f2b8eac79567 
Mon, 07 Mar 2016 17:39:40 E:\mana_api\mana_api\api\pm_mana.py[line:116] ERROR Error with get pm_accounts
Traceback (most recent call last):
  File "E:\mana_api\mana_api\api\pm_mana.py", line 113, in pm_bill
    result = get_pm_accounts(tenant_id)
  File "E:\mana_api\mana_api\apiUtil.py", line 324, in get_pm_accounts
    month_dict[p]['month'] = pm_month_dict[p]['month']
KeyError: u'2015-12#beijing'
Mon, 07 Mar 2016 17:39:40 C:\Python27\lib\site-packages\werkzeug-0.10.4-py2.7.egg\werkzeug\_internal.py[line:87] INFO 192.168.39.170 - - [07/Mar/2016 17:39:40] "GET /mana_api/pm_bill?tenant_id=74d4bda6aa1c466d8cb1f2b8eac79567 HTTP/1.1" 400 -
Mon, 07 Mar 2016 17:40:45 C:\Python27\lib\site-packages\werkzeug-0.10.4-py2.7.egg\werkzeug\_internal.py[line:87] INFO  * Detected change in 'E:\\mana_api\\mana_api\\apiUtil.py', reloading
Mon, 07 Mar 2016 17:40:45 C:\Python27\lib\site-packages\werkzeug-0.10.4-py2.7.egg\werkzeug\_internal.py[line:87] INFO  * Restarting with stat
Mon, 07 Mar 2016 17:40:50 E:\mana_api\mana_api\api\pm_mana.py[line:110] INFO Request: get pm accounts tenant_id => 74d4bda6aa1c466d8cb1f2b8eac79567 
Mon, 07 Mar 2016 17:40:50 C:\Python27\lib\site-packages\werkzeug-0.10.4-py2.7.egg\werkzeug\_internal.py[line:87] INFO 192.168.39.170 - - [07/Mar/2016 17:40:50] "GET /mana_api/pm_bill?tenant_id=74d4bda6aa1c466d8cb1f2b8eac79567 HTTP/1.1" 200 -
